Workbook
Name ACCEPTANCE: #REF!
Name ARTIFACT: #REF!
Name DTYPE: #REF!
Name PHASE: #REF!
Name PHASE_OF_ORIGIN: #REF!
Name REVIEW_OBJECTS: #REF!
Name REVIEW_TYPE: #REF!
Name SEVERITY: #REF!
Name VENUE: #REF!
Name VENUE: #REF!
Name VENUE: #REF!
Name VENUE: #REF!
Name VENUE: #REF!
Name VENUE: #REF!
Name VENUE: #REF!
Name VENUE: #REF!
Name VENUE: #REF!
Name VENUE: #REF!
Name VENUE: #REF!
Name VENUE: #REF!
Name VENUE: #REF!
Name VENUE: #REF!

Sheet Game Summary
A1: Game Concept | T1: Payouts in credits
A2: Mechanics | D2: Variant | E2: Module ID | T2: Bet multiplier | U2: 10 | V2: Lines | W2: 40
A3: 40 Lines Left - Right | D3: V94 | E3: 102571 | O3: Paytable | T3: Bet (cents) | U3: 2500
A4: Highest pay per line | O4: Pattern | P4: 3Hit | Q4: 4Hit | R4: 5Hit | T4: Pattern | U4: 3Hit | V4: 4Hit | W4: 5Hit
A5: 4x5 Slot Grid | O5: =BaseA!M4 -> H1 | P5: =BaseA!N4 -> 20 | Q5: =BaseA!O4 -> 80 | R5: =BaseA!P4 -> 400 | T5: H1 | U5: =P5*$U$3/$W$2 -> 1250 | V5: =Q5*$U$3/$W$2 -> 5000 | W5: =R5*$U$3/$W$2 -> 25000
A6: $$$ QH wins | O6: H2 | P6: =BaseA!N5 -> 16 | Q6: =BaseA!O5 -> 60 | R6: =BaseA!P5 -> 200 | T6: H2 | U6: =P6*$U$3/$W$2 -> 1000 | V6: =Q6*$U$3/$W$2 -> 3750 | W6: =R6*$U$3/$W$2 -> 12500
A7: 4 Different Lock it Link bonus game | O7: H3 | P7: =BaseA!N6 -> 12 | Q7: =BaseA!O6 -> 40 | R7: =BaseA!P6 -> 120 | T7: H3 | U7: =P7*$U$3/$W$2 -> 750 | V7: =Q7*$U$3/$W$2 -> 2500 | W7: =R7*$U$3/$W$2 -> 7500
A8: Minimum bet 0.10 | O8: H4 | P8: =BaseA!N7 -> 8 | Q8: =BaseA!O7 -> 28 | R8: =BaseA!P7 -> 80 | T8: H4 | U8: =P8*$U$3/$W$2 -> 500 | V8: =Q8*$U$3/$W$2 -> 1750 | W8: =R8*$U$3/$W$2 -> 5000
O9: H5 | P9: =BaseA!N8 -> 8 | Q9: =BaseA!O8 -> 28 | R9: =BaseA!P8 -> 80 | T9: H5 | U9: =P9*$U$3/$W$2 -> 500 | V9: =Q9*$U$3/$W$2 -> 1750 | W9: =R9*$U$3/$W$2 -> 5000
A10: Symbols | O10: L1 | P10: =BaseA!N9 -> 8 | Q10: =BaseA!O9 -> 16 | R10: =BaseA!P9 -> 60 | T10: L1 | U10: =P10*$U$3/$W$2 -> 500 | V10: =Q10*$U$3/$W$2 -> 1000 | W10: =R10*$U$3/$W$2 -> 3750
A11: Character Symbols - H1, H2, H3, H4, H5 | O11: L2 | P11: =BaseA!N10 -> 8 | Q11: =BaseA!O10 -> 16 | R11: =BaseA!P10 -> 60 | T11: L2 | U11: =P11*$U$3/$W$2 -> 500 | V11: =Q11*$U$3/$W$2 -> 1000 | W11: =R11*$U$3/$W$2 -> 3750
A12: Card Symbols - L1, L2, L3, L4 | O12: L3 | P12: =BaseA!N11 -> 4 | Q12: =BaseA!O11 -> 12 | R12: =BaseA!P11 -> 40 | T12: L3 | U12: =P12*$U$3/$W$2 -> 250 | V12: =Q12*$U$3/$W$2 -> 750 | W12: =R12*$U$3/$W$2 -> 2500
A13: rn1 - turns to any symbol except QH and Collect symbols | O13: L4 | P13: =BaseA!N12 -> 4 | Q13: =BaseA!O12 -> 12 | R13: =BaseA!P12 -> 40 | T13: L4 | U13: =P13*$U$3/$W$2 -> 250 | V13: =Q13*$U$3/$W$2 -> 750 | W13: =R13*$U$3/$W$2 -> 2500
A14: Wild - "W" replaces any symbol except QH and Collect symbols | O14: W | P14: =BaseA!N13 -> 40 | Q14: =BaseA!O13 -> 200 | R14: =BaseA!P13 -> 1000 | T14: W | U14: =P14*$U$3/$W$2 -> 2500 | V14: =Q14*$U$3/$W$2 -> 12500 | W14: =R14*$U$3/$W$2 -> 62500 | X14: ← Max symbol payout
A15: QH - each of these symbol turns to a random win value (0.5x, 2x, 3x, 4x, up to 50x). Fills the cup and can trigger Bonus Game
A16: C - appears on BaseB and BaseC on Reel1 and Reel5 and triggers immediate win for any QHs appearing on Reels
O17: RTP Breakdown (Theoretical)
A18: Base Collect Feature | P18: RTP | Q18: Hit Rate | R18: SD | S18: Hit chance | T18: 1 in X spins | U18: Average Win (times bet)
A19: Collect symbol "C" appearing on reel1 and reel5 will award multiplier win on any QHs appearing on the Reels | O19: Base Payline: | P19: =Summary!B16 -> 0.37003551 | Q19: =MathSheet!E3 - Q20 -> 0.19192362 | R19: =MathSheet!E5 -> 3.2267684 | T19: =1/Q19 -> 5.2104061
A20: Each QHs will generate random value from 0.5x to 50x the totalbet | O20: Base Collect: | P20: =Summary!B17 -> 0.33600494 | Q20: =MathSheet!E24 -> 0.045661841 | T20: =1/Q20 -> 21.900125
A21: The QHs have Four different types and can trigger 4 different types of Bonus game | O21: Bonus Game1: | P21: =Summary!G24 -> 0.055556591 | S21: =Summary!D24 -> 0.0019345391 | T21: =1/S21 -> 516.91898 | U21: =Summary!F24 -> 28.718256
B22: Note: | C22: Only 1 Bonus game can be trigger per paid spin with the ff. order of priority Bonus1, Bonus2, Bonus3, Bonus4 | O22: Bonus Game2: | P22: =Summary!G25 -> 0.055773065 | S22: =Summary!D25 -> 0.0017989158 | T22: =1/S22 -> 555.8904 | U22: =Summary!F25 -> 31.003711
O23: Bonus Game3: | P23: =Summary!G26 -> 0.056884678 | S23: =Summary!D26 -> 0.0017352203 | T23: =1/S23 -> 576.2957 | U23: =Summary!F26 -> 32.782395
A24: Jackpot Collect Feature | O24: Bonus Game4: | P24: =Summary!G27 -> 0.057069563 | S24: =Summary!D27 -> 0.0016725909 | T24: =1/S24 -> 597.87482 | U24: =Summary!F27 -> 34.120455
A25: Everytime BaseA is selected there is a chance a subscript is attached on a normal symbol or Wild symbol | O25: Jackpots: | P25: =MathSheet!B6 -> 0.013040893 | S25: =MathSheet!I43 -> 0.00042829406 | T25: =1/S25 -> 2334.8444 | U25: =P25/S25 -> 30.448455
A26: This subscript will add values to any of the Four jackpots | O26: Full Game: | P26: =SUM(P19:P25) -> 0.94436523 | Q26: =MathSheet!E4 -> 0.2426232 | R26: =MathSheet!E6 -> 5.6772444 | S26: =SUM(S19:S24) -> 0.0071412662 | T26: =1/S26 -> 140.03119
A27: During any of the 4 bonus game, a Jackpot Token can be attached on a QH symbol but not on Maximizer nor any of the 4 Bonus Feature symbol
A28: This token will fill one of the four Jackpot Meter | O28: RTP Strategies
A29: Once a meter is fllled, Jackpot will then be awarded and resets back to its starting value after the Bonus session. | O29: Strategy/Variant | P29: RTP | Q29: Hit Rate | R29: Variance | S29: Standard Deviation | T29: Volatility Index at a 95% Level of Confidence | U29: Volatility Category
A30: Each Jackpot type can only be awarded one time per bonus session
B31: Type | C31: Increment Value | D31: Min Jackpot Win | E31: Max Jackpot Win | F31: No. of Tokens Required | O31: RandomBet | P31: =$P$26 -> 0.94436523 | Q31: =$Q$26 -> 0.2426232 | R31: =POWER(S31, 2) -> 32.231104 | S31: =$R$26 -> 5.6772444 | T31: =S31*1.96 -> 11.127399 | U31: Medium | V31: https://gamesglobal.atlassian.net/wiki/spaces/PGM/pages/274680477/Maths+Terms+FAQ#MathsTermsFAQ-WhatisVolatility?
B32: Mini | C32: 0.5 | D32: 10 | E32: 20 | F32: 2 | O32: MaxBet | P32: =$P$26 -> 0.94436523 | Q32: =$Q$26 -> 0.2426232 | R32: =POWER(S32, 2) -> 32.231104 | S32: =$R$26 -> 5.6772444 | T32: =S32*1.96 -> 11.127399 | U32: Medium | V32: A Volatility less than 10 is considered Low, between 10 and 20 is considered Medium and above 20 is considered High.
B33: Minor | C33: 2 | D33: 30 | E33: 50 | F33: 3
B34: Major | C34: 5 | D34: 250 | E34: 500 | F34: 4 | O34: Max Win / Max Odds
B35: Grand | C35: 10 | D35: 5000 | E35: 10000 | F35: 5 | O35: Max Win | P35: =MathSheet!H6 -> 10000 | Q35: x totalbet
O36: Max Win Chance | P36: =MathSheet!H7 -> 6.0134176e-08 | Q36: or 1 in | R36: =1/P36 -> 16629479
B37: Note: | C37: In Base game, if a certain jackpot type reaches its maximum value then the increment will randomly choose other jackpot type | O37: Max Odds | P37: =MathSheet!J7 -> 16629479
O38: Max Exposure | P38: =P70*P35 -> 25000000 | Q38: =P38/100 -> 250000 | R38: credits
A40: Bonus Game1 - w Fireball Feature | O40: Free Game Statistics
A41: Played on two 4x5 slot grid | O41: Probability of Getting a Win w/in X Spins | P41: 5 | Q41: 10 | R41: 20 | S41: 50 | T41: 100
...

Sheet Market Summary
D2: 94 Variant | E2: 92 Variant
C3: RTP | D3: 0.94436523 | E3: 0.9242577
C4: Variance | D4: =D6^2 -> 32.231104 | E4: =E6^2 -> 29.339847
C5: Hit Rate % | D5: 0.2426232 | E5: 0.24226096
C6: Standard deviation | D6: 5.6772444 | E6: 5.4166269
C7: Volatility Index Based on a 95% Level of Confidence | D7: 11.12773 | E7: 10.61743
A9: USA | C9: State: | D9: New Jersey
D10: 94 | E10: 92
C11: Highest Advertised Win Odds (1 in X) | D11: 16629479 | E11: 18133545
C12: How is it achieved? | D12: Winning Grand Jackpot by filling Grand Jackpot Meter in any of the 4 Bonus Games
C14: NB: | D14: The highest pay in the prize-first distribution or the highest paying award is to be used as the Top Award for the game
C16: State: | D16: Michigan
D17: 94 | E17: 92
C18: Highest Advertised Win Odds (1 in X) | D18: =D11 -> 16629479 | E18: =E11 -> 18133545
C19: Highest Advertised Win Odds (X : 1) | D19: =D18-1 -> 16629478 | E19: =E18-1 -> 18133544
C20: How is it achieved? | D20: =D12 -> Winning Grand Jackpot by filling Grand Jackpot Meter in any of the 4 Bonus Games
C22: NB: | D22: The highest pay in the prize-first distribution or the highest paying award is to be used as the Top Award for the game
C24: State: | D24: Connecticut
D25: 94 | E25: 92
C26: Highest Advertised Win Odds (1 in X) | D26: =D18 -> 16629479 | E26: =E18 -> 18133545
C27: Highest Advertised Win Odds (X : 1) | D27: =D19 -> 16629478 | E27: =E19 -> 18133544
C28: How is it achieved? | D28: =D20 -> Winning Grand Jackpot by filling Grand Jackpot Meter in any of the 4 Bonus Games
C30: NB: | D30: The highest pay in the prize-first distribution or the highest paying award is to be used as the Top Award for the game
C32: State: | D32: Pennsylvania
D33: 94 | E33: 92
C34: Highest Advertised Win Odds (1 in X) | D34: =D26 -> 16629479 | E34: =E26 -> 18133545
C35: How is it achieved? | D35: =D28 -> Winning Grand Jackpot by filling Grand Jackpot Meter in any of the 4 Bonus Games
C38: NB: | D38: The highest pay in the prize-first distribution or the highest paying award is to be used as the Top Award for the game
C39: Worst Odds (1 in X) | D39: =D34 -> 16629479 | E39: =E34 -> 18133545
C40: How is it achieved? | D40: =D35 -> Winning Grand Jackpot by filling Grand Jackpot Meter in any of the 4 Bonus Games
C42: NB: | D42: The smallest odds from ALL unique awards.
C44: Win-Caps | D44: 94 | E44: 92
C45: Does this game have a Win-Cap? | D45: NO
C46: Possible Answers:
C47: Yes
C48: Odds (1 in X) | D48: N/A | E48: N/A
C49: %RTP Shaved | D49: N/A | E49: N/A
C50: No
C51: How is this achieved?
C54: Game Math Derivation
...

Sheet Change Log
A1: Changes from Old V1 94%
A2: 1.) Maximum of only 3 Mirror Feature can appear per spin on Bonus Game4
A3: 2.) Maximizer Feature cannot appear at the same time with Mirror Feature on Bonus Game4
A4: 3.) New Mirror Feature Trigger Chance for Bonus Game4. "MathSheet" E64
A6: Changes from V1 94%
A7: 1.) New BaseA Reelset. "Row_Structure"
A8: 2.) New Base %Distribution. "MathSheet" B10:B12
A9: 3.) New Base Coin Conversion Chance to Bonus Game. "MathSheet" G53:G56
A10: 4.) New Jackpot Increment Values. "MathSheet" C39:C42

Sheet Flow_Chart
A1: FlowChart
AB2: Bonus Game
M24: Yes
K29: No
D36: Yes
M37: Yes | T37: Yes
AT39: No
F40: No
K41: No | AI41: Yes
Q42: No | AD42: Yes | AO42: No | AV42: Yes
AK44: No
AB47: No | AM47: Yes
AO52: No
Z54: Yes
AM55: Yes
AC58: No | AO58: No
AO61: Yes

Sheet MathSheet
A1: Math Sheet
A3: Base RTP: | B3: =Summary!B16 -> 0.37003551 | D3: Base Hit Rate: | E3: =Heat_map_graph_FG!D59 -> 0.23758546 | G3: Base Win Rate: | H3: =SUM(Heat_map_graph_FG!D37:D58) -> 0.125727
A4: Base Collect Feature RTP: | B4: =Summary!B17 -> 0.33600494 | D4: Full Game Hit Rate: | E4: =Heat_map_graph_FG!D27 -> 0.2426232 | G4: Full Game Win Rate: | H4: =SUM(Heat_map_graph_FG!D5:D26) -> 0.13169962
A5: Bonus RTP: | B5: =Summary!B18 -> 0.2252839 | D5: Base SD: | E5: 3.2267684
A6: Jackpot RTP: | B6: =Summary!B19 -> 0.013040893 | D6: Full Game SD: | E6: 5.6772444 | G6: Max Win: | H6: =Summary!N18 -> 10000 | I6: x totalbet
A7: Total: | B7: =SUM(B3:B6) -> 0.94436523 | D7: Volatility index (95%) | E7: 11.12773 | F7: =NORMDIST(E7, B7-1, E6, TRUE) - NORMDIST(-E7, B7-1, E6, TRUE) -> 0.95000002 | G7: Chance(Pulls/Hit): | H7: =Summary!R18 -> 6.0134176e-08 | I7: or 1 in | J7: =1/H7 -> 16629479 | K7: spins
A9: Base Reelset Distribution | B9: =Summary!B2 -> Chance | C9: =Summary!C2 -> RTP | D9: =Summary!D2 -> EV | E9: =Summary!F2 -> Base RTP | F9: =Summary!G2 -> EV | H9: BaseQH Distribution | I9: BaseB | K9: BaseC
A10: =Summary!A3 -> BaseA | B10: =Summary!B3 -> 0.72 | C10: =Summary!C3 -> 0.48924808 | D10: =Summary!D3 -> 0.35225862 | E10: =Summary!F3 -> 0.48924808 | F10: =Summary!G3 -> 0.35225862 | H10: =BaseB!N24 -> QH Multiplier/Symbol | I10: =BaseB!O24 -> Chance | J10: =BaseB!P24 -> EV | K10: =BaseC!O24 -> Chance | L10: =BaseC!P24 -> EV
A11: =Summary!A4 -> BaseB | B11: =Summary!B4 -> 0.24 | C11: =Summary!C4 -> 2.2487377 | D11: =Summary!D4 -> 0.53969705 | E11: =Summary!F4 -> 1.4412014 | F11: =Summary!G4 -> 0.34588833 | H11: =BaseB!N25 -> 0.5 | I11: =BaseB!O25 -> 0.2781 | J11: =BaseB!P25 -> 0.13905 | K11: =BaseC!O25 -> 0.05 | L11: =BaseC!P25 -> 0.025
A12: =Summary!A5 -> BaseC | B12: =Summary!B5 -> 0.04 | C12: =Summary!C5 -> 0.98421665 | D12: =Summary!D5 -> 0.039368666 | E12: =Summary!F5 -> 0.19733723 | F12: =Summary!G5 -> 0.0078934894 | H12: =BaseB!N26 -> 1 | I12: =BaseB!O26 -> 0.27 | J12: =BaseB!P26 -> 0.27 | K12: =BaseC!O26 -> 0.05 | L12: =BaseC!P26 -> 0.05
B13: =Summary!B6 -> 1 | D13: =Summary!D6 -> 0.93132434 | F13: =SUM(F10:F12) -> 0.70604044 | H13: =BaseB!N27 -> 1.5 | I13: =BaseB!O27 -> 0.12 | J13: =BaseB!P27 -> 0.18 | K13: =BaseC!O27 -> 0.05 | L13: =BaseC!P27 -> 0.075
H14: =BaseB!N28 -> 2 | I14: =BaseB!O28 -> 0.09 | J14: =BaseB!P28 -> 0.18 | K14: =BaseC!O28 -> 0.05 | L14: =BaseC!P28 -> 0.1
H15: =BaseB!N29 -> 2.5 | I15: =BaseB!O29 -> 0.06 | J15: =BaseB!P29 -> 0.15 | K15: =BaseC!O29 -> 0.05 | L15: =BaseC!P29 -> 0.125
A16: Random Symbols | B16: BaseA | D16: =Summary!F8 -> Type of Coin in Base in BaseB and BaseC | E16: =Summary!G8 -> Chance | H16: =BaseB!N30 -> 3 | I16: =BaseB!O30 -> 0.04 | J16: =BaseB!P30 -> 0.12 | K16: =BaseC!O30 -> 0.05 | L16: =BaseC!P30 -> 0.15
A17: =BaseA!N25 -> H1 | B17: =BaseA!O25 -> 0.07 | D17: =Summary!F9 -> Bronze | E17: =Summary!G9 -> 0.25 | H17: =BaseB!N31 -> 3.5 | I17: =BaseB!O31 -> 0.03 | J17: =BaseB!P31 -> 0.105 | K17: =BaseC!O31 -> 0.05 | L17: =BaseC!P31 -> 0.175
A18: =BaseA!N26 -> H2 | B18: =BaseA!O26 -> 0.08 | D18: =Summary!F10 -> Silver | E18: =Summary!G10 -> 0.25 | H18: =BaseB!N32 -> 4 | I18: =BaseB!O32 -> 0.025 | J18: =BaseB!P32 -> 0.1 | K18: =BaseC!O32 -> 0.05 | L18: =BaseC!P32 -> 0.2
A19: =BaseA!N27 -> H3 | B19: =BaseA!O27 -> 0.1 | D19: =Summary!F11 -> Gold | E19: =Summary!G11 -> 0.25 | H19: =BaseB!N33 -> 5 | I19: =BaseB!O33 -> 0.02 | J19: =BaseB!P33 -> 0.1 | K19: =BaseC!O33 -> 0.05 | L19: =BaseC!P33 -> 0.25
A20: =BaseA!N28 -> H4 | B20: =BaseA!O28 -> 0.11 | D20: =Summary!F12 -> Platinum | E20: =Summary!G12 -> 0.25 | H20: =BaseB!N34 -> 6 | I20: =BaseB!O34 -> 0.015 | J20: =BaseB!P34 -> 0.09 | K20: =BaseC!O34 -> 0.05 | L20: =BaseC!P34 -> 0.3
A21: =BaseA!N29 -> H5 | B21: =BaseA!O29 -> 0.11 | E21: =Summary!G13 -> 1 | H21: =BaseB!N35 -> 7 | I21: =BaseB!O35 -> 0.012 | J21: =BaseB!P35 -> 0.084 | K21: =BaseC!O35 -> 0.05 | L21: =BaseC!P35 -> 0.35
A22: =BaseA!N30 -> L1 | B22: =BaseA!O30 -> 0.12 | H22: =BaseB!N36 -> 8 | I22: =BaseB!O36 -> 0.01 | J22: =BaseB!P36 -> 0.08 | K22: =BaseC!O36 -> 0.05 | L22: =BaseC!P36 -> 0.4
A23: =BaseA!N31 -> L2 | B23: =BaseA!O31 -> 0.12 | D23: QH Collect Feature | H23: =BaseB!N37 -> 9 | I23: =BaseB!O37 -> 0.008 | J23: =BaseB!P37 -> 0.072 | K23: =BaseC!O37 -> 0.05 | L23: =BaseC!P37 -> 0.45
A24: =BaseA!N32 -> L3 | B24: =BaseA!O32 -> 0.14 | D24: =Summary!A12 -> Collect Win Chance: | E24: =Summary!B12 -> 0.045661841 | F24: =Summary!C12 -> or 1 in | G24: =Summary!D12 -> 21.900125 | H24: =BaseB!N38 -> 10 | I24: =BaseB!O38 -> 0.006 | J24: =BaseB!P38 -> 0.06 | K24: =BaseC!O38 -> 0.05 | L24: =BaseC!P38 -> 0.5
A25: =BaseA!N33 -> L4 | B25: =BaseA!O33 -> 0.13 | D25: =Summary!A13 -> Collect RTP: | E25: =Summary!B13 -> 0.33600494 | H25: =BaseB!N39 -> 12 | I25: =BaseB!O39 -> 0.005 | J25: =BaseB!P39 -> 0.06 | K25: =BaseC!O39 -> 0.05 | L25: =BaseC!P39 -> 0.6
A26: =BaseA!N34 -> W | B26: =BaseA!O34 -> 0.02 | D26: =Summary!A14 -> Collect Ave Win: | E26: =Summary!B14 -> 7.35855 | F26: x totalbet | H26: =BaseB!N40 -> 15 | I26: =BaseB!O40 -> 0.004 | J26: =BaseB!P40 -> 0.06 | K26: =BaseC!O40 -> 0.05 | L26: =BaseC!P40 -> 0.75
B27: =SUM(B17:B26) -> 1 | H27: =BaseB!N41 -> 20 | I27: =BaseB!O41 -> 0.003 | J27: =BaseB!P41 -> 0.06 | K27: =BaseC!O41 -> 0.04 | L27: =BaseC!P41 -> 0.8
H28: =BaseB!N42 -> 25 | I28: =BaseB!O42 -> 0.002 | J28: =BaseB!P42 -> 0.05 | K28: =BaseC!O42 -> 0.04 | L28: =BaseC!P42 -> 1
H29: =BaseB!N43 -> 30 | I29: =BaseB!O43 -> 0.001 | J29: =BaseB!P43 -> 0.03 | K29: =BaseC!O43 -> 0.04 | L29: =BaseC!P43 -> 1.2
H30: =BaseB!N44 -> 40 | I30: =BaseB!O44 -> 0.0005 | J30: =BaseB!P44 -> 0.02 | K30: =BaseC!O44 -> 0.04 | L30: =BaseC!P44 -> 1.6
H31: =BaseB!N45 -> 50 | I31: =BaseB!O45 -> 0.0004 | J31: =BaseB!P45 -> 0.02 | K31: =BaseC!O45 -> 0.04 | L31: =BaseC!P45 -> 2
I32: =SUM(I11:I31) -> 1 | J32: =SUM(J11:J31) -> 2.03005 | K32: =SUM(K11:K31) -> 1 | L32: =SUM(L11:L31) -> 11.1
A33: Jackpot
A34: =Summary!J10 -> Chance of Increment in BaseA: | B34: =Summary!K10 -> 0.4
A35: =Summary!J11 -> Chance of Increment: | B35: =Summary!K11 -> 0.288 | C35: =Summary!L11 -> or 1 in | D35: =Summary!M11 -> 3.4722222
A36: =Summary!J13 -> Bonus Game Token Chance: | B36: =Summary!K13 -> 0.16
A38: =Summary!J14 -> Type | B38: =Summary!K14 -> Increment %Distribution | C38: =Summary!L14 -> Increment Value | D38: =Summary!M14 -> Min Jackpot Win | E38: =Summary!N14 -> Max Jackpot Win | F38: =Summary!O14 -> Average Win | G38: =Summary!P14 -> Token %Distribution | H38: =Summary!Q14 -> No. of Tokens Required | ... K38: =Summary!T14 -> Jackpot Pulls/Hit
A39: =Summary!J15 -> Mini | B39: =Summary!K15 -> 0.25 | C39: =Summary!L15 -> 0.5 | D39: =Summary!M15 -> 10 | E39: =Summary!N15 -> 20 | F39: =Summary!O15 -> 19.907802 | G39: =Summary!P15 -> 0.26 | H39: =Summary!Q15 -> 2 | ... K39: =Summary!T15 -> 2828.8112
A40: =Summary!J16 -> Midi | B40: =Summary!K16 -> 0.25 | C40: =Summary!L16 -> 2 | D40: =Summary!M16 -> 30 | E40: =Summary!N16 -> 50 | F40: =Summary!O16 -> 49.980773 | G40: =Summary!P16 -> 0.31 | H40: =Summary!Q16 -> 3 | ... K40: =Summary!T16 -> 14079.799
A41: =Summary!J17 -> Maxi | B41: =Summary!K17 -> 0.25 | C41: =Summary!L17 -> 5 | D41: =Summary!M17 -> 250 | E41: =Summary!N17 -> 500 | F41: =Summary!O17 -> 499.95123 | G41: =Summary!P17 -> 0.25 | H41: =Summary!Q17 -> 4 | ... K41: =Summary!T17 -> 269920.89
A42: =Summary!J18 -> Grand | B42: =Summary!K18 -> 0.25 | C42: =Summary!L18 -> 10 | D42: =Summary!M18 -> 5000 | E42: =Summary!N18 -> 10000 | F42: =Summary!O18 -> 10000 | G42: =Summary!P18 -> 0.18 | H42: =Summary!Q18 -> 5 | ... K42: =Summary!T18 -> 16629479
B43: =Summary!K19 -> 1 | G43: =Summary!P19 -> 1 | I43: =SUM(I39:I42) -> 0.00042829406 | J43: =Summary!S19 -> 0.013040893 | K43: =1/I43 -> 2334.8444
...

Sheet Summary
A1: Summary
B2: Chance | C2: RTP | D2: EV | F2: Base RTP | G2: EV | J2: Collect Bonus Game
A3: BaseA | B3: =1 - SUM(B4:B5) -> 0.72 | C3: =BaseA!H1 -> 0.48924808 | D3: =B3 * C3 -> 0.35225862 | F3: =BaseA!E1 -> 0.48924808 | G3: =B3 * F3 -> 0.35225862 | J3: Bonus Type | K3: Ave no. of Coins to Cup | L3: Coin Conversion to Bonus Game | M3: Bonus Game Chance | N3: Pulls/Hit
A4: BaseB | B4: 0.24 | C4: =BaseB!H1 -> 2.2487377 | D4: =B4 * C4 -> 0.53969705 | F4: =BaseB!E1+BaseB!K1 -> 1.4412014 | G4: =B4 * F4 -> 0.34588833 | J4: Bonus1 | K4: =BaseB!I92 * B4 + BaseC!I84 * B5 -> 0.1758672 | L4: =BaseB!O68 -> 0.011 | M4: =B4 * BaseB!P68 + B5 * BaseC!P68 -> 0.0019345391 | N4: =1/M4 -> 516.91898
A5: BaseC | B5: 0.04 | C5: =BaseC!H1 -> 0.98421665 | D5: =B5 * C5 -> 0.039368666 | F5: =BaseC!E1+BaseC!K1 -> 0.19733723 | G5: =B5 * F5 -> 0.0078934894 | J5: Bonus2 | K5: =B4 * BaseB!J92 + B5 * BaseC!J84 -> 0.1758672 | L5: =BaseB!O69 -> 0.0103 | M5: =B4 * BaseB!P69 + B5 * BaseC!P69 -> 0.0017989158 | N5: =1/M5 -> 555.8904
B6: =SUM(B3:B5) -> 1 | D6: =SUM(D3:D5) -> 0.93132434 | G6: =SUM(G3:G5) -> 0.70604044 | J6: Bonus3 | K6: =B4 * BaseB!K92 + B5 * BaseC!K84 -> 0.1758672 | L6: =BaseB!O70 -> 0.01 | M6: =B4 * BaseB!P70 + B5 * BaseC!P70 -> 0.0017352203 | N6: =1/M6 -> 576.2957
J7: Bonus4 | K7: =B4 * BaseB!L92 + B5 * BaseC!L84 -> 0.1758672 | L7: =BaseB!O71 -> 0.0097 | M7: =B4 * BaseB!P71 + B5 * BaseC!P71 -> 0.0016725909 | N7: =1/M7 -> 597.87482
A8: Bonus Ave Win: | B8: =H28 -> 31.546772 | F8: Type of Coin in Base in BaseB and BaseC | G8: Chance | M8: =SUM(M4:M7) -> 0.0071412662 | N8: =1/M8 -> 140.03119
A9: Bonus Chance: | B9: =D28 -> 0.0071412662 | C9: or 1 in | D9: =1/B9 -> 140.03119 | F9: Bronze | G9: =BaseB!H66 -> 0.25
A10: Bonus RTP: | B10: =B8*B9 -> 0.2252839 | F10: Silver | G10: =BaseB!H67 -> 0.25 | J10: Chance of Increment in BaseA: | K10: 0.4
F11: Gold | G11: =BaseB!H68 -> 0.25 | J11: Chance of Increment: | K11: =K10 * B3 -> 0.288 | L11: or 1 in | M11: =1/K11 -> 3.4722222
A12: Collect Win Chance: | B12: =B4 * G16 + B5 * H16 -> 0.045661841 | C12: or 1 in | D12: =1/B12 -> 21.900125 | F12: Platinum | G12: =BaseB!H69 -> 0.25
A13: Collect RTP: | B13: =G18 * B4 + H18 * B5 -> 0.33600494 | G13: =SUM(G9:G12) -> 1 | J13: Bonus Game Token Chance: | K13: =Bonus_Game1!M$29 -> 0.16
A14: Collect Ave Win: | B14: =B13/B12 -> 7.35855 | J14: Type | K14: Increment %Distribution | L14: Increment Value | M14: Min Jackpot Win | N14: Max Jackpot Win | O14: Average Win | P14: Token %Distribution | Q14: No. of Tokens Required | R14: Jackpot Hit Chance | S14: RTP | T14: Jackpot Pulls/Hit
G15: =A4 -> BaseB | H15: =A5 -> BaseC | J15: =Bonus_Game1!L33 -> Mini | K15: =100%/4 -> 0.25 | L15: 0.5 | M15: 10 | N15: 20 | O15: 19.907802 | P15: =Bonus_Game1!N33 -> 0.26 | Q15: 2 | R15: =M$4 * Bonus_Game1!O33 + M$5 * Bonus_Game2!O33 + M$6 * Bonus_Game3!O33 + M$7 * Bonus_Game4!O33 -> 0.00035350539 | S15: =O15*R15 -> 0.0070375153 | T15: =1/R15 -> 2828.8112
A16: Payline RTP: | B16: =G6-B13 -> 0.37003551 | F16: Collect Win Chance: | G16: =1 - ( (1-BaseB!B40 ) * (1 - BaseB!E40 ) ) -> 0.18971374 | H16: =BaseC!B39 -> 0.0032635469 | J16: =Bonus_Game1!L34 -> Midi | K16: =100%/4 -> 0.25 | L16: 2 | M16: 30 | N16: 50 | O16: 49.980773 | P16: =Bonus_Game1!N34 -> 0.31 | Q16: 3 | R16: =M$4 * Bonus_Game1!O34 + M$5 * Bonus_Game2!O34 + M$6 * Bonus_Game3!O34 + M$7 * Bonus_Game4!O34 -> 7.1023742e-05 | S16: =O16*R16 -> 0.0035498216 | T16: =1/R16 -> 14079.799
A17: Collect RTP: | B17: =B13 -> 0.33600494 | F17: Collect Ave Win: | G17: =G18/G16 -> 7.2581712 | H17: =H18/H16 -> 42.369357 | J17: =Bonus_Game1!L35 -> Maxi | K17: =100%/4 -> 0.25 | L17: 5 | M17: 250 | N17: 500 | O17: 499.95123 | P17: =Bonus_Game1!N35 -> 0.25 | Q17: 4 | R17: =M$4 * Bonus_Game1!O35 + M$5 * Bonus_Game2!O35 + M$6 * Bonus_Game3!O35 + M$7 * Bonus_Game4!O35 -> 3.7047892e-06 | S17: =O17*R17 -> 0.0018522139 | T17: =1/R17 -> 269920.89
A18: Bonus Game RTP: | B18: =G28 -> 0.2252839 | F18: Collect RTP: | G18: =BaseB!K1 -> 1.3769748 | H18: =BaseC!K1 -> 0.13827438 | J18: =Bonus_Game1!L36 -> Grand | K18: =100%/4 -> 0.25 | L18: 10 | M18: 5000 | N18: 10000 | O18: 10000 | P18: =Bonus_Game1!N36 -> 0.18 | Q18: 5 | R18: =M$4 * Bonus_Game1!O36 + M$5 * Bonus_Game2!O36 + M$6 * Bonus_Game3!O36 + M$7 * Bonus_Game4!O36 -> 6.0134176e-08 | S18: =O18*R18 -> 0.00060134176 | T18: =1/R18 -> 16629479
A19: Jackpot RTP: | B19: =S19 -> 0.013040893 | K19: =SUM(K15:K18) -> 1 | P19: =SUM(P15:P18) -> 1 | R19: =SUM(R15:R18) -> 0.00042829406 | S19: =SUM(S15:S18) -> 0.013040893 | T19: =1/R19 -> 2334.8444
B20: =SUM(B16:B19) -> 0.94436523
A23: Bonus Type | B23: Symbol hit per slot | C23: Ave no. of Symbol hits | D23: Chance | E23: Pulls/hit | F23: Ave Win | G23: EV | H23: Total Ave Win
A24: Bonus1 | B24: =Bonus_Game1!B4 -> 0.039 | C24: =Bonus_Game1!I71 -> 13.714566 | D24: =M4 -> 0.0019345391 | E24: =1/D24 -> 516.91898 | F24: =BaseB!N15 -> 28.718256 | G24: =D24 * F24 -> 0.055556591 | H24: =D24/D$28 * F24 -> 7.7796556
A25: Bonus2 | B25: =Bonus_Game2!B4 -> 0.039 | C25: =Bonus_Game2!I71 -> 13.63257 | D25: =M5 -> 0.0017989158 | E25: =1/D25 -> 555.8904 | F25: =BaseB!O15 -> 31.003711 | G25: =D25 * F25 -> 0.055773065 | H25: =D25/D$28 * F25 -> 7.8099686
A26: Bonus3 | B26: =Bonus_Game3!B4 -> 0.039 | C26: =Bonus_Game3!I71 -> 13.301109 | D26: =M6 -> 0.0017352203 | E26: =1/D26 -> 576.2957 | F26: =BaseB!P15 -> 32.782395 | G26: =D26 * F26 -> 0.056884678 | H26: =D26/D$28 * F26 -> 7.9656292
A27: Bonus4 | B27: =Bonus_Game4!B4 -> 0.039 | C27: =Bonus_Game4!I71 -> 18.261442 | D27: =M7 -> 0.0016725909 | E27: =1/D27 -> 597.87482 | F27: =BaseB!Q15 -> 34.120455 | G27: =D27 * F27 -> 0.057069563 | H27: =D27/D$28 * F27 -> 7.9915189
D28: =SUM(D24:D27) -> 0.0071412662 | E28: =1/D28 -> 140.03119 | G28: =SUM(G24:G27) -> 0.2252839 | H28: =SUM(H24:H27) -> 31.546772

Sheet BaseA
A1: BaseA | D1: RTP: | E1: =Q35 -> 0.48924808 | G1: Final RTP: | H1: =E1 + K1 -> 0.48924808
A2: Number of Symbol | H2: Chances | M2: Math Payout
A3: Pattern | B3: Reel1 | C3: Reel2 | D3: Reel3 | E3: Reel4 | F3: Reel5 | H3: Pattern | I3: 3Hit | J3: 4Hit | K3: 5Hit | M3: Pattern | N3: =I3 -> 3Hit | O3: =J3 -> 4Hit | P3: =K3 -> 5Hit
A4: H1 | B4: 7 | C4: 6 | D4: 7 | E4: 6 | F4: 7 | H4: =A4 -> H1 | I4: =(B25+B$34)/B$38 * (C25+C$34)/C$38 * (D25+D$34)/D$38 * (E$38-E25-E$34)/E$38 - (B$34)/B$38 * (C$34)/C$38 * (D$34)/D$38 * (E$38-E25-E$34)/E$38 -> 0.00078593421 | J4: =(B25+B$34)/B$38 * (C25+C$34)/C$38 * (D25+D$34)/D$38 * (E25+E$34)/E$38 * (F$38 - F25-F$34)/F$38 - (B$34)/B$38 * (C$34)/C$38 * (D$34)/D$38 * (E$34)/E$38 * (F$38 - F25-F$34)/F$38 -> 7.2192513e-05 | K4: =(B25+B$34)/B$38 * (C25+C$34)/C$38 * (D25+D$34)/D$38 * (E25+E$34)/E$38 * (F25+F$34)/F$38 - (B$34)/B$38 * (C$34)/C$38 * (D$34)/D$38 * (E$34)/E$38 * (F$34)/F$38 -> 8.0781073e-06 | M4: =H4 -> H1 | N4: 20 | O4: 80 | P4: 400
A5: H2 | B5: 8 | C5: 8 | D5: 8 | E5: 8 | F5: 8 | H5: =A5 -> H2 | I5: =(B26+B$34)/B$38 * (C26+C$34)/C$38 * (D26+D$34)/D$38 * (E$38-E26-E$34)/E$38 - (B$34)/B$38 * (C$34)/C$38 * (D$34)/D$38 * (E$38-E26-E$34)/E$38 -> 0.0011478621 | J5: =(B26+B$34)/B$38 * (C26+C$34)/C$38 * (D26+D$34)/D$38 * (E26+E$34)/E$38 * (F$38 - F26-F$34)/F$38 - (B$34)/B$38 * (C$34)/C$38 * (D$34)/D$38 * (E$34)/E$38 * (F$38 - F26-F$34)/F$38 -> 0.00012962263 | K5: =(B26+B$34)/B$38 * (C26+C$34)/C$38 * (D26+D$34)/D$38 * (E26+E$34)/E$38 * (F26+F$34)/F$38 - (B$34)/B$38 * (C$34)/C$38 * (D$34)/D$38 * (E$34)/E$38 * (F26 + F$34)/F$38 -> 1.6020774e-05 | M5: =H5 -> H2 | N5: 16 | O5: 60 | P5: 200
A6: H3 | B6: 9 | C6: 9 | D6: 10 | E6: 9 | F6: 9 | H6: =A6 -> H3 | I6: =(B27+B$34)/B$38 * (C27+C$34)/C$38 * (D27+D$34)/D$38 * (E$38-E27-E$34)/E$38 - (B$34)/B$38 * (C$34)/C$38 * (D$34)/D$38 * (E$38-E27-E$34)/E$38 -> 0.0016056285 | J6: =(B27+B$34)/B$38 * (C27+C$34)/C$38 * (D27+D$34)/D$38 * (E27+E$34)/E$38 * (F$38 - F27-F$34)/F$38 - (B$34)/B$38 * (C$34)/C$38 * (D$34)/D$38 * (E27 + E$34)/E$38 * (F$38 - F27-F$34)/F$38 -> 0.00019489008 | K6: =(B27+B$34)/B$38 * (C27+C$34)/C$38 * (D27+D$34)/D$38 * (E27+E$34)/E$38 * (F27+F$34)/F$38 - (B$34)/B$38 * (C$34)/C$38 * (D$34)/D$38 * (E$34)/E$38 * (F27 + F$34)/F$38 -> 2.6867607e-05 | M6: =H6 -> H3 | N6: 12 | O6: 40 | P6: 120
A7: H4 | B7: 11 | C7: 10 | D7: 11 | E7: 10 | F7: 11 | H7: =A7 -> H4 | I7: =(B28+B$34)/B$38 * (C28+C$34)/C$38 * (D28+D$34)/D$38 * (E$38-E28-E$34)/E$38 - (B$34)/B$38 * (C$34)/C$38 * (D$34)/D$38 * (E$38-E28-E$34)/E$38 -> 0.0021687063 | J7: =(B28+B$34)/B$38 * (C28+C$34)/C$38 * (D28+D$34)/D$38 * (E28+E$34)/E$38 * (F$38 - F28-F$34)/F$38 - (B$34)/B$38 * (C$34)/C$38 * (D$34)/D$38 * (E28 + E$34)/E$38 * (F$38 - F28-F$34)/F$38 -> 0.00028193182 | K7: =(B28+B$34)/B$38 * (C28+C$34)/C$38 * (D28+D$34)/D$38 * (E28+E$34)/E$38 * (F28+F$34)/F$38 - (B$34)/B$38 * (C$34)/C$38 * (D$34)/D$38 * (E$34)/E$38 * (F28 + F$34)/F$38 -> 4.627399e-05 | M7: =H7 -> H4 | N7: 8 | O7: 28 | P7: 80
A8: H5 | B8: 11 | C8: 11 | D8: 11 | E8: 11 | F8: 11 | H8: =A8 -> H5 | I8: =(B29+B$34)/B$38 * (C29+C$34)/C$38 * (D29+D$34)/D$38 * (E$38-E29-E$34)/E$38 - (B$34)/B$38 * (C$34)/C$38 * (D$34)/D$38 * (E$38-E29-E$34)/E$38 -> 0.0023101384 | J8: =(B29+B$34)/B$38 * (C29+C$34)/C$38 * (D29+D$34)/D$38 * (E29+E$34)/E$38 * (F$38 - F29-F$34)/F$38 - (B$34)/B$38 * (C$34)/C$38 * (D$34)/D$38 * (E29 + E$34)/E$38 * (F$38 - F29-F$34)/F$38 -> 0.00032722431 | K8: =(B29+B$34)/B$38 * (C29+C$34)/C$38 * (D29+D$34)/D$38 * (E29+E$34)/E$38 * (F29+F$34)/F$38 - (B$34)/B$38 * (C$34)/C$38 * (D$34)/D$38 * (E$34)/E$38 * (F29 + F$34)/F$38 -> 5.3684998e-05 | M8: =H8 -> H5 | N8: 8 | O8: 28 | P8: 80
A9: L1 | B9: 12 | C9: 12 | D9: 12 | E9: 12 | F9: 12 | H9: =A9 -> L1 | I9: =(B30+B$34)/B$38 * (C30+C$34)/C$38 * (D30+D$34)/D$38 * (E$38-E30-E$34)/E$38 - (B$34)/B$38 * (C$34)/C$38 * (D$34)/D$38 * (E$38-E30-E$34)/E$38 -> 0.0028131583 | J9: =(B30+B$34)/B$38 * (C30+C$34)/C$38 * (D30+D$34)/D$38 * (E30+E$34)/E$38 * (F$38 - F30-F$34)/F$38 - (B$34)/B$38 * (C$34)/C$38 * (D$34)/D$38 * (E30 + E$34)/E$38 * (F$38 - F30-F$34)/F$38 -> 0.00042699725 | K9: =(B30+B$34)/B$38 * (C30+C$34)/C$38 * (D30+D$34)/D$38 * (E30+E$34)/E$38 * (F30+F$34)/F$38 - (B$34)/B$38 * (C$34)/C$38 * (D$34)/D$38 * (E$34)/E$38 * (F30 + F$34)/F$38 -> 7.58386e-05 | M9: =H9 -> L1 | N9: 8 | O9: 16 | P9: 60
A10: L2 | B10: 12 | C10: 12 | D10: 12 | E10: 12 | F10: 12 | H10: =A10 -> L2 | I10: =(B31+B$34)/B$38 * (C31+C$34)/C$38 * (D31+D$34)/D$38 * (E$38-E31-E$34)/E$38 - (B$34)/B$38 * (C$34)/C$38 * (D$34)/D$38 * (E$38-E31-E$34)/E$38 -> 0.0028131583 | J10: =(B31+B$34)/B$38 * (C31+C$34)/C$38 * (D31+D$34)/D$38 * (E31+E$34)/E$38 * (F$38 - F31-F$34)/F$38 - (B$34)/B$38 * (C$34)/C$38 * (D$34)/D$38 * (E31 + E$34)/E$38 * (F$38 - F31-F$34)/F$38 -> 0.00042699725 | K10: =(B31+B$34)/B$38 * (C31+C$34)/C$38 * (D31+D$34)/D$38 * (E31+E$34)/E$38 * (F31+F$34)/F$38 - (B$34)/B$38 * (C$34)/C$38 * (D$34)/D$38 * (E$34)/E$38 * (F31 + F$34)/F$38 -> 7.58386e-05 | M10: =H10 -> L2 | N10: 8 | O10: 16 | P10: 60
A11: L3 | B11: 13 | C11: 14 | D11: 14 | E11: 14 | F11: 13 | H11: =A11 -> L3 | I11: =(B32+B$34)/B$38 * (C32+C$34)/C$38 * (D32+D$34)/D$38 * (E$38-E32-E$34)/E$38 - (B$34)/B$38 * (C$34)/C$38 * (D$34)/D$38 * (E$38-E32-E$34)/E$38 -> 0.0037706637 | J11: =(B32+B$34)/B$38 * (C32+C$34)/C$38 * (D32+D$34)/D$38 * (E32+E$34)/E$38 * (F$38 - F32-F$34)/F$38 - (B$34)/B$38 * (C$34)/C$38 * (D$34)/D$38 * (E32 + E$34)/E$38 * (F$38 - F32-F$34)/F$38 -> 0.00065664728 | K11: =(B32+B$34)/B$38 * (C32+C$34)/C$38 * (D32+D$34)/D$38 * (E32+E$34)/E$38 * (F32+F$34)/F$38 - (B$34)/B$38 * (C$34)/C$38 * (D$34)/D$38 * (E32+E$34)/E$38 * (F32 + F$34)/F$38 -> 0.00012507567 | M11: =H11 -> L3 | N11: 4 | O11: 12 | P11: 40
A12: L4 | B12: 14 | C12: 14 | D12: 14 | E12: 14 | F12: 14 | H12: =A12 -> L4 | I12: =(B33+B$34)/B$38 * (C33+C$34)/C$38 * (D33+D$34)/D$38 * (E$38-E33-E$34)/E$38 - (B$34)/B$38 * (C$34)/C$38 * (D$34)/D$38 * (E$38-E33-E$34)/E$38 -> 0.0040077143 | J12: =(B33+B$34)/B$38 * (C33+C$34)/C$38 * (D33+D$34)/D$38 * (E33+E$34)/E$38 * (F$38 - F33-F$34)/F$38 - (B$34)/B$38 * (C$34)/C$38 * (D$34)/D$38 * (E33 + E$34)/E$38 * (F$38 - F33-F$34)/F$38 -> 0.00068962011 | K12: =(B33+B$34)/B$38 * (C33+C$34)/C$38 * (D33+D$34)/D$38 * (E33+E$34)/E$38 * (F33+F$34)/F$38 - (B$34)/B$38 * (C$34)/C$38 * (D$34)/D$38 * (E33+E$34)/E$38 * (F33 + F$34)/F$38 -> 0.00014124749 | M12: =H12 -> L4 | N12: 4 | O12: 12 | P12: 40
A13: W | B13: 3 | C13: 3 | D13: 3 | E13: 3 | F13: 3 | H13: =A13 -> W | I13: =(B$34)/B$38 * (C$34)/C$38 * (D$34)/D$38 * (E$38 - E$34-E25-E26)/E$38 - (B$34)/B$38 * (C$34)/C$38 * (D$34)/D$38 * ( E27/E38 * (F27 + F34)/F38 + E28/E38 * (F28 + F34)/F38 + E29/E38 * (F29 + F34)/F38 + E30/E38 * (F30+F34)/F38 + E31/E38 * (F31+F34)/F38 ) -> 2.0088586e-05 | J13: =(B$34)/B$38 * (C$34)/C$38 * (D$34)/D$38 * (E$34)/E$38 * (F$38 - F$34-F25)/F$38 -> 7.2921731e-07 | K13: =(B$34)/B$38 * (C$34)/C$38 * (D$34)/D$38 * (E$34)/E$38 * (F$34)/F$38 -> 2.4307244e-08 | M13: =H13 -> W | N13: 40 | O13: 200 | P13: 1000
A14: rn1 | B14: 17 | C14: 17 | D14: 17 | E14: 16 | F14: 15
A16: QH | B16: 0 | C16: 0 | D16: 0 | E16: 0 | F16: 0
A17: Total | B17: =SUM(B4:B16) -> 117 | C17: =SUM(C4:C16) -> 116 | D17: =SUM(D4:D16) -> 119 | E17: =SUM(E4:E16) -> 115 | F17: =SUM(F4:F16) -> 115
H23: EV
H24: =H3 -> Pattern | I24: =I3 -> 3Hit | J24: =J3 -> 4Hit | K24: =K3 -> 5Hit | L24: Total | N24: Random Symbols | O24: Chance | P24: RTP | Q24: EV
A25: =A4 -> H1 | B25: =B4 + B51 -> 7 | C25: =C4 + C51 -> 6 | D25: =D4 + D51 -> 7 | E25: =E4 + E51 -> 6 | F25: =F4 + F51 -> 7 | H25: =A4 -> H1 | I25: =I4 * N4 -> 0.015718684 | J25: =J4 * O4 -> 0.0057754011 | K25: =K4 * P4 -> 0.0032312429 | L25: =SUM(I25:K25) -> 0.024725328 | N25: =H25 -> H1 | O25: 0.07 | P25: 0.71154416 | Q25: =O25 * P25 -> 0.049808091 | S25: =SUM(O$25:O25) * 100 -> 7
A26: =A5 -> H2 | B26: =B5 + B52 -> 8 | C26: =C5 + C52 -> 8 | D26: =D5 + D52 -> 8 | E26: =E5 + E52 -> 8 | F26: =F5 + F52 -> 8 | H26: =A5 -> H2 | I26: =I5 * N5 -> 0.018365793 | J26: =J5 * O5 -> 0.0077773577 | K26: =K5 * P5 -> 0.0032041548 | L26: =SUM(I26:K26) -> 0.029347305 | N26: =H26 -> H2 | O26: 0.08 | P26: 0.60242233 | Q26: =O26 * P26 -> 0.048193786 | S26: =SUM(O$25:O26) * 100 -> 15
A27: =A6 -> H3 | B27: =B6 + B53 -> 9 | C27: =C6 + C53 -> 9 | D27: =D6 + D53 -> 10 | E27: =E6 + E53 -> 9 | F27: =F6 + F53 -> 9 | H27: =A6 -> H3 | I27: =I6 * N6 -> 0.019267542 | J27: =J6 * O6 -> 0.0077956031 | K27: =K6 * P6 -> 0.0032241128 | L27: =SUM(I27:K27) -> 0.030287258 | N27: =H27 -> H3 | O27: 0.1 | P27: 0.50832918 | Q27: =O27 * P27 -> 0.050832918 | S27: =SUM(O$25:O27) * 100 -> 25
A28: =A7 -> H4 | B28: =B7 + B54 -> 11 | C28: =C7 + C54 -> 10 | D28: =D7 + D54 -> 11 | E28: =E7 + E54 -> 10 | F28: =F7 + F54 -> 11 | H28: =A7 -> H4 | I28: =I7 * N7 -> 0.01734965 | J28: =J7 * O7 -> 0.0078940908 | K28: =K7 * P7 -> 0.0037019192 | L28: =SUM(I28:K28) -> 0.02894566 | N28: =H28 -> H4 | O28: 0.11 | P28: 0.43579211 | Q28: =O28 * P28 -> 0.047937133 | S28: =SUM(O$25:O28) * 100 -> 36
A29: =A8 -> H5 | B29: =B8 + B55 -> 11 | C29: =C8 + C55 -> 11 | D29: =D8 + D55 -> 11 | E29: =E8 + E55 -> 11 | F29: =F8 + F55 -> 11 | H29: =A8 -> H5 | I29: =I8 * N8 -> 0.018481107 | J29: =J8 * O8 -> 0.0091622808 | K29: =K8 * P8 -> 0.0042947999 | L29: =SUM(I29:K29) -> 0.031938188 | N29: =H29 -> H5 | O29: 0.11 | P29: 0.44911079 | Q29: =O29 * P29 -> 0.049402187 | S29: =SUM(O$25:O29) * 100 -> 47
A30: =A9 -> L1 | B30: =B9 + B56 -> 12 | C30: =C9 + C56 -> 12 | D30: =D9 + D56 -> 12 | E30: =E9 + E56 -> 12 | F30: =F9 + F56 -> 12 | H30: =A9 -> L1 | I30: =I9 * N9 -> 0.022505267 | J30: =J9 * O9 -> 0.0068319559 | K30: =K9 * P9 -> 0.004550316 | L30: =SUM(I30:K30) -> 0.033887538 | N30: =H30 -> L1 | O30: 0.12 | P30: 0.40964367 | Q30: =O30 * P30 -> 0.049157241 | S30: =SUM(O$25:O30) * 100 -> 59
A31: =A10 -> L2 | B31: =B10 + B57 -> 12 | C31: =C10 + C57 -> 12 | D31: =D10 + D57 -> 12 | E31: =E10 + E57 -> 12 | F31: =F10 + F57 -> 12 | H31: =A10 -> L2 | I31: =I10 * N10 -> 0.022505267 | J31: =J10 * O10 -> 0.0068319559 | K31: =K10 * P10 -> 0.004550316 | L31: =SUM(I31:K31) -> 0.033887538 | N31: =H31 -> L2 | O31: 0.12 | P31: 0.40964367 | Q31: =O31 * P31 -> 0.049157241 | S31: =SUM(O$25:O31) * 100 -> 71
A32: =A11 -> L3 | B32: =B11 + B58 -> 13 | C32: =C11 + C58 -> 14 | D32: =D11 + D58 -> 14 | E32: =E11 + E58 -> 14 | F32: =F11 + F58 -> 13 | H32: =A11 -> L3 | I32: =I11 * N11 -> 0.015082655 | J32: =J11 * O11 -> 0.0078797674 | K32: =K11 * P11 -> 0.0050030269 | L32: =SUM(I32:K32) -> 0.027965449 | N32: =H32 -> L3 | O32: 0.14 | P32: 0.34463585 | Q32: =O32 * P32 -> 0.048249019 | S32: =SUM(O$25:O32) * 100 -> 85
A33: =A12 -> L4 | B33: =B12 + B59 -> 14 | C33: =C12 + C59 -> 14 | D33: =D12 + D59 -> 14 | E33: =E12 + E59 -> 14 | F33: =F12 + F59 -> 14 | H33: =A12 -> L4 | I33: =I12 * N12 -> 0.016030857 | J33: =J12 * O12 -> 0.0082754413 | K33: =K12 * P12 -> 0.0056498997 | L33: =SUM(I33:K33) -> 0.029956198 | N33: =H33 -> L4 | O33: 0.13 | P33: 0.35125209 | Q33: =O33 * P33 -> 0.045662772 | S33: =SUM(O$25:O33) * 100 -> 98
A34: =A13 -> W | B34: =B13 + B60 -> 3 | C34: =C13 + C60 -> 3 | D34: =D13 + D60 -> 3 | E34: =E13 + E60 -> 3 | F34: =F13 + F60 -> 3 | H34: =A13 -> W | I34: =I13 * N13 -> 0.00080354346 | J34: =J13 * O13 -> 0.00014584346 | K34: =K13 * P13 -> 2.4307244e-05 | L34: =SUM(I34:K34) -> 0.00097369416 | N34: =H34 -> W | O34: 0.02 | P34: 2.5423849 | Q34: =O34 * P34 -> 0.050847698 | S34: =SUM(O$25:O34) * 100 -> 100
O35: =SUM(O25:O34) -> 1 | Q35: =SUM(Q25:Q34) -> 0.48924808
A37: =A16 -> QH | B37: =B16 -> 0 | C37: =C16 -> 0 | D37: =D16 -> 0 | E37: =E16 -> 0 | F37: =F16 -> 0
B38: =SUM(B25:B37) -> 100 | C38: =SUM(C25:C37) -> 99 | D38: =SUM(D25:D37) -> 102 | E38: =SUM(E25:E37) -> 99 | F38: =SUM(F25:F37) -> 100
I39: =SUM(I25:I38) -> 0.16611036 | J39: =SUM(J25:J38) -> 0.068369697 | K39: =SUM(K25:K38) -> 0.037434095 | L39: =SUM(L25:L38) -> 0.27191416
A51: =A25 -> H1
A52: =A26 -> H2
A53: =A27 -> H3
A54: =A28 -> H4
A55: =A29 -> H5
A56: =A30 -> L1
A57: =A31 -> L2
A58: =A32 -> L3
...

Sheet BaseA_Structure
A1: "H5", | B1: "L3", | C1: "L3", | D1: "H5", | E1: "L1",
A2: "H5", | B2: "L3", | C2: "L3", | D2: "H5", | E2: "L1",
A3: "H5", | B3: "L3", | C3: "L3", | D3: "H5", | E3: "L3",
A4: "L3", | B4: "H4", | C4: "H2", | D4: "L1", | E4: "L3",
A5: "L3", | B5: "H4", | C5: "H2", | D5: "L1", | E5: "L3",
A6: "H4", | B6: "H4", | C6: "H4", | D6: "W", | E6: "H4",
A7: "H4", | B7: "H5", | C7: "H4", | D7: "L3", | E7: "H4", | G7: rn1,
A8: "W", | B8: "H5", | C8: "L2", | D8: "L3", | E8: "W",
A9: "L2", | B9: "H5", | C9: "L2", | D9: "L3", | E9: "H2",
A10: "L2", | B10: "L2", | C10: "W", | D10: "H4", | E10: "H2", | G10: "W",
A11: "H3", | B11: "L2", | C11: "H3", | D11: "H4", | E11: "H5",
A12: "H3", | B12: "H3", | C12: "H3", | D12: "H4", | E12: "H5",
A13: "L1", | B13: "H3", | C13: "H2", | D13: rn1, | E13: rn1,
A14: "L1", | B14: "H2", | C14: "H2", | D14: rn1, | E14: rn1,
A15: "H2", | B15: "H2", | C15: "H4", | D15: rn1, | E15: rn1,
A16: "H2", | B16: "H4", | C16: "H4", | D16: rn1, | E16: rn1,
A17: "H4", | B17: "H4", | C17: "H5", | D17: rn1, | E17: rn1,
A18: "H4", | B18: "L3", | C18: "H5", | D18: rn1, | E18: rn1,
A19: "H2", | B19: "L3", | C19: "H5", | D19: rn1, | E19: rn1,
A20: "H2", | B20: "H2", | C20: "L3", | D20: rn1, | E20: rn1,
A21: "H1", | B21: "H2", | C21: "L3", | D21: rn1, | E21: rn1,
A22: "H1", | B22: "W", | C22: "W", | D22: "L2", | E22: "H5",
... A115: "H2", | B115: "L3", | C115: "H5", | D115: "H1", | E115: "H1",
A116: "H2", | B116: "H1", | C116: "H5",
A117: "H1", | C117: "L3",
C118: "L3",
C119: "H1",

Sheet BaseB
A1: BaseB | D1: RTP: | E1: =L39 -> 0.064226549 | G1: Final RTP: | H1: =E1 + K1 + N1 -> 2.2487377 | J1: QH RTP: | K1: =B20 * F20 + B21 * F21 -> 1.3769748 | M1: Bonus RTP: | N1: =I15 * N15 + J15 * O15 + K15 * P15 + L15 * Q15 -> 0.80753633
A2: Number of Symbol | H2: Chances | M2: Math Payout
A3: Pattern | B3: Reel1 | C3: Reel2 | D3: Reel3 | E3: Reel4 | F3: Reel5 | H3: Pattern | I3: 3Hit | J3: 4Hit | K3: 5Hit | M3: Pattern | N3: =I3 -> 3Hit | O3: =J3 -> 4Hit | P3: =K3 -> 5Hit
A4: H1 | B4: 3 | C4: 3 | D4: 3 | E4: 3 | F4: 3 | H4: =A4 -> H1 | I4: =(B4+B$13)/B$17 * (C4+C$13)/C$17 * (D4+D$13)/D$17 * (E$17-E4-E$13)/E$17 - (B$13)/B$17 * (C$13)/C$17 * (D$13)/D$17 * (E$17-E4-E$13)/E$17 -> 6.2246274e-05 | J4: =(B4+B$13)/B$17 * (C4+C$13)/C$17 * (D4+D$13)/D$17 * (E4+E$13)/E$17 * (F$17 - F4-F$13)/F$17 - (B$13)/B$17 * (C$13)/C$17 * (D$13)/D$17 * (E$13)/E$17 * (F$17 - F4-F$13)/F$17 -> 2.5263036e-06 | K4: =(B4+B$13)/B$17 * (C4+C$13)/C$17 * (D4+D$13)/D$17 * (E4+E$13)/E$17 * (F4+F$13)/F$17 - (B$13)/B$17 * (C$13)/C$17 * (D$13)/D$17 * (E$13)/E$17 * (F$13)/F$17 -> 1.0382069e-07 | M4: =H4 -> H1 | N4: =BaseA!N4 -> 20 | O4: =BaseA!O4 -> 80 | P4: =BaseA!P4 -> 400
A5: H2 | B5: 4 | C5: 4 | D5: 4 | E5: 4 | F5: 4 | H5: =A5 -> H2 | I5: =(B5+B$13)/B$17 * (C5+C$13)/C$17 * (D5+D$13)/D$17 * (E$17-E5-E$13)/E$17 - (B$13)/B$17 * (C$13)/C$17 * (D$13)/D$17 * (E$17-E5-E$13)/E$17 -> 0.0001454686 | J5: =(B5+B$13)/B$17 * (C5+C$13)/C$17 * (D5+D$13)/D$17 * (E5+E$13)/E$17 * (F$17 - F5-F$13)/F$17 - (B$13)/B$17 * (C$13)/C$17 * (D$13)/D$17 * (E$13)/E$17 * (F$17 - F5-F$13)/F$17 -> 7.8749919e-06 | K5: =(B5+B$13)/B$17 * (C5+C$13)/C$17 * (D5+D$13)/D$17 * (E5+E$13)/E$17 * (F5+F$13)/F$17 - (B$13)/B$17 * (C$13)/C$17 * (D$13)/D$17 * (E$13)/E$17 * (F5 + F$13)/F$17 -> 4.3749955e-07 | M5: =H5 -> H2 | N5: =BaseA!N5 -> 16 | O5: =BaseA!O5 -> 60 | P5: =BaseA!P5 -> 200
A6: H3 | B6: 5 | C6: 5 | D6: 5 | E6: 5 | F6: 5 | H6: =A6 -> H3 | I6: =(B6+B$13)/B$17 * (C6+C$13)/C$17 * (D6+D$13)/D$17 * (E$17-E6-E$13)/E$17 - (B$13)/B$17 * (C$13)/C$17 * (D$13)/D$17 * (E$17-E6-E$13)/E$17 -> 0.00028005953 | J6: =(B6+B$13)/B$17 * (C6+C$13)/C$17 * (D6+D$13)/D$17 * (E6+E$13)/E$17 * (F$17 - F6-F$13)/F$17 - (B$13)/B$17 * (C$13)/C$17 * (D$13)/D$17 * (E6 + E$13)/E$17 * (F$17 - F6-F$13)/F$17 -> 1.8959026e-05 | K6: =(B6+B$13)/B$17 * (C6+C$13)/C$17 * (D6+D$13)/D$17 * (E6+E$13)/E$17 * (F6+F$13)/F$17 - (B$13)/B$17 * (C$13)/C$17 * (D$13)/D$17 * (E$13)/E$17 * (F6 + F$13)/F$17 -> 1.3351427e-06 | M6: =H6 -> H3 | N6: =BaseA!N6 -> 12 | O6: =BaseA!O6 -> 40 | P6: =BaseA!P6 -> 120
A7: H4 | B7: 6 | C7: 6 | D7: 6 | E7: 6 | F7: 6 | H7: =A7 -> H4 | I7: =(B7+B$13)/B$17 * (C7+C$13)/C$17 * (D7+D$13)/D$17 * (E$17-E7-E$13)/E$17 - (B$13)/B$17 * (C$13)/C$17 * (D$13)/D$17 * (E$17-E7-E$13)/E$17 -> 0.0004769292 | J7: =(B7+B$13)/B$17 * (C7+C$13)/C$17 * (D7+D$13)/D$17 * (E7+E$13)/E$17 * (F$17 - F7-F$13)/F$17 - (B$13)/B$17 * (C$13)/C$17 * (D$13)/D$17 * (E7 + E$13)/E$17 * (F$17 - F7-F$13)/F$17 -> 3.8759726e-05 | K7: =(B7+B$13)/B$17 * (C7+C$13)/C$17 * (D7+D$13)/D$17 * (E7+E$13)/E$17 * (F7+F$13)/F$17 - (B$13)/B$17 * (C$13)/C$17 * (D$13)/D$17 * (E$13)/E$17 * (F7 + F$13)/F$17 -> 3.3222622e-06 | M7: =H7 -> H4 | N7: =BaseA!N7 -> 8 | O7: =BaseA!O7 -> 28 | P7: =BaseA!P7 -> 80
A8: H5 | B8: 7 | C8: 7 | D8: 7 | E8: 7 | F8: 7 | H8: =A8 -> H5 | I8: =(B8+B$13)/B$17 * (C8+C$13)/C$17 * (D8+D$13)/D$17 * (E$17-E8-E$13)/E$17 - (B$13)/B$17 * (C$13)/C$17 * (D$13)/D$17 * (E$17-E8-E$13)/E$17 -> 0.00074620846 | J8: =(B8+B$13)/B$17 * (C8+C$13)/C$17 * (D8+D$13)/D$17 * (E8+E$13)/E$17 * (F$17 - F8-F$13)/F$17 - (B$13)/B$17 * (C$13)/C$17 * (D$13)/D$17 * (E8 + E$13)/E$17 * (F$17 - F8-F$13)/F$17 -> 7.0781361e-05 | K8: =(B8+B$13)/B$17 * (C8+C$13)/C$17 * (D8+D$13)/D$17 * (E8+E$13)/E$17 * (F8+F$13)/F$17 - (B$13)/B$17 * (C$13)/C$17 * (D$13)/D$17 * (E$13)/E$17 * (F8 + F$13)/F$17 -> 7.1807177e-06 | M8: =H8 -> H5 | N8: =BaseA!N8 -> 8 | O8: =BaseA!O8 -> 28 | P8: =BaseA!P8 -> 80
A9: L1 | B9: 8 | C9: 8 | D9: 8 | E9: 8 | F9: 8 | H9: =A9 -> L1 | I9: =(B9+B$13)/B$17 * (C9+C$13)/C$17 * (D9+D$13)/D$17 * (E$17-E9-E$13)/E$17 - (B$13)/B$17 * (C$13)/C$17 * (D$13)/D$17 * (E$17-E9-E$13)/E$17 -> 0.0010972489 | J9: =(B9+B$13)/B$17 * (C9+C$13)/C$17 * (D9+D$13)/D$17 * (E9+E$13)/E$17 * (F$17 - F9-F$13)/F$17 - (B$13)/B$17 * (C$13)/C$17 * (D$13)/D$17 * (E9 + E$13)/E$17 * (F$17 - F9-F$13)/F$17 -> 0.00011899988 | K9: =(B9+B$13)/B$17 * (C9+C$13)/C$17 * (D9+D$13)/D$17 * (E9+E$13)/E$17 * (F9+F$13)/F$17 - (B$13)/B$17 * (C$13)/C$17 * (D$13)/D$17 * (E$13)/E$17 * (F9 + F$13)/F$17 -> 1.3999986e-05 | M9: =H9 -> L1 | N9: =BaseA!N9 -> 8 | O9: =BaseA!O9 -> 16 | P9: =BaseA!P9 -> 60
A10: L2 | B10: 8 | C10: 8 | D10: 8 | E10: 8 | F10: 8 | H10: =A10 -> L2 | I10: =(B10+B$13)/B$17 * (C10+C$13)/C$17 * (D10+D$13)/D$17 * (E$17-E10-E$13)/E$17 - (B$13)/B$17 * (C$13)/C$17 * (D$13)/D$17 * (E$17-E10-E$13)/E$17 -> 0.0010972489 | J10: =(B10+B$13)/B$17 * (C10+C$13)/C$17 * (D10+D$13)/D$17 * (E10+E$13)/E$17 * (F$17 - F10-F$13)/F$17 - (B$13)/B$17 * (C$13)/C$17 * (D$13)/D$17 * (E10 + E$13)/E$17 * (F$17 - F10-F$13)/F$17 -> 0.00011899988 | K10: =(B10+B$13)/B$17 * (C10+C$13)/C$17 * (D10+D$13)/D$17 * (E10+E$13)/E$17 * (F10+F$13)/F$17 - (B$13)/B$17 * (C$13)/C$17 * (D$13)/D$17 * (E$13)/E$17 * (F10 + F$13)/F$17 -> 1.3999986e-05 | M10: =H10 -> L2 | N10: =BaseA!N10 -> 8 | O10: =BaseA!O10 -> 16 | P10: =BaseA!P10 -> 60
A11: L3 | B11: 9 | C11: 9 | D11: 9 | E11: 9 | F11: 9 | H11: =A11 -> L3 | I11: =(B11+B$13)/B$17 * (C11+C$13)/C$17 * (D11+D$13)/D$17 * (E$17-E11-E$13)/E$17 - (B$13)/B$17 * (C$13)/C$17 * (D$13)/D$17 * (E$17-E11-E$13)/E$17 -> 0.0015386227 | J11: =(B11+B$13)/B$17 * (C11+C$13)/C$17 * (D11+D$13)/D$17 * (E11+E$13)/E$17 * (F$17 - F11-F$13)/F$17 - (B$13)/B$17 * (C$13)/C$17 * (D$13)/D$17 * (E11 + E$13)/E$17 * (F$17 - F11-F$13)/F$17 -> 0.00018781164 | K11: =(B11+B$13)/B$17 * (C11+C$13)/C$17 * (D11+D$13)/D$17 * (E11+E$13)/E$17 * (F11+F$13)/F$17 - (B$13)/B$17 * (C$13)/C$17 * (D$13)/D$17 * (E11+E$13)/E$17 * (F11 + F$13)/F$17 -> 2.5228429e-05 | M11: =H11 -> L3 | N11: =BaseA!N11 -> 4 | O11: =BaseA!O11 -> 12 | P11: =BaseA!P11 -> 40
A12: L4 | B12: 9 | C12: 9 | D12: 9 | E12: 9 | F12: 9 | H12: =A12 -> L4 | I12: =(B12+B$13)/B$17 * (C12+C$13)/C$17 * (D12+D$13)/D$17 * (E$17-E12-E$13)/E$17 - (B$13)/B$17 * (C$13)/C$17 * (D$13)/D$17 * (E$17-E12-E$13)/E$17 -> 0.0015386227 | J12: =(B12+B$13)/B$17 * (C12+C$13)/C$17 * (D12+D$13)/D$17 * (E12+E$13)/E$17 * (F$17 - F12-F$13)/F$17 - (B$13)/B$17 * (C$13)/C$17 * (D$13)/D$17 * (E12 + E$13)/E$17 * (F$17 - F12-F$13)/F$17 -> 0.00018781164 | K12: =(B12+B$13)/B$17 * (C12+C$13)/C$17 * (D12+D$13)/D$17 * (E12+E$13)/E$17 * (F12+F$13)/F$17 - (B$13)/B$17 * (C$13)/C$17 * (D$13)/D$17 * (E12+E$13)/E$17 * (F12 + F$13)/F$17 -> 2.5228429e-05 | M12: =H12 -> L4 | N12: =BaseA!N12 -> 4 | O12: =BaseA!O12 -> 12 | P12: =BaseA!P12 -> 40
A13: W | B13: 0 | C13: 0 | D13: 0 | E13: 0 | F13: 0 | H13: =A13 -> W | I13: =(B$13)/B$17 * (C$13)/C$17 * (D$13)/D$17 * (E$17 - E$13-E4-E5)/E$17 - (B$13)/B$17 * (C$13)/C$17 * (D$13)/D$17 * ( E6/E17 * (F6 + F13)/F17 + E7/E17 * (F7 + F13)/F17 + E8/E17 * (F8 + F13)/F17 + E9/E17 * (F9+F13)/F17 + E10/E17 * (F10+F13)/F17 ) -> 0 | J13: =(B$13)/B$17 * (C$13)/C$17 * (D$13)/D$17 * (E$13)/E$17 * (F$17 - F$13-F4)/F$17 -> 0 | K13: =(B$13)/B$17 * (C$13)/C$17 * (D$13)/D$17 * (E$13)/E$17 * (F$13)/F$17 -> 0 | M13: =H13 -> W | N13: =BaseA!N13 -> 40 | O13: =BaseA!O13 -> 200 | P13: =BaseA!P13 -> 1000
A15: C | B15: 2 | C15: 0 | D15: 0 | E15: 0 | F15: 2 | H15: Bonus Game: | I15: =P68 -> 0.0069346635 | J15: =P69 -> 0.0064483374 | K15: =P70 -> 0.0062198699 | L15: =P71 -> 0.0059952386 | M15: =H15 -> Bonus Game: | N15: =Bonus_Game1!B22 -> 28.718256 | O15: =Bonus_Game2!B22 -> 31.003711 | P15: =Bonus_Game3!B22 -> 32.782395 | Q15: =Bonus_Game4!B22 -> 34.120455
A16: QH | B16: =B56 * 3 + B57 * 2 + B58 * 1 -> 15 | C16: =C56 * 3 + C57 * 2 + C58 * 1 -> 15 | D16: =D56 * 3 + D57 * 2 + D58 * 1 -> 15 | E16: =E56 * 3 + E57 * 2 + E58 * 1 -> 15 | F16: =F56 * 3 + F57 * 2 + F58 * 1 -> 15
A17: Total | B17: =SUM(B4:B16) -> 76 | C17: =SUM(C4:C16) -> 74 | D17: =SUM(D4:D16) -> 74 | E17: =SUM(E4:E16) -> 74 | F17: =SUM(F4:F16) -> 76
A20: Chance of Collect(Collect on Reel1): | B20: =B15 * 4 / B17 -> 0.10526316 | C20: or 1 in | D20: =1/B20 -> 9.5 | E20: QH Ave Win(Collect on Reel1): | F20: =SUM(C27:F27) -> 6.5406305
A21: Chance of Collect(Collect on Reel5): | B21: =F15/F17 * 4 -> 0.10526316 | C21: or 1 in | D21: =1/B21 -> 9.5 | E21: QH Ave Win(Collect on Reel5): | F21: =SUM(B27:E27) -> 6.5406305
H23: EV
B24: =B3 -> Reel1 | C24: =C3 -> Reel2 | D24: =D3 -> Reel3 | E24: =E3 -> Reel4 | F24: =F3 -> Reel5 | H24: =H3 -> Pattern | I24: =I3 -> 3Hit | J24: =J3 -> 4Hit | K24: =K3 -> 5Hit | L24: Total | N24: QH Multiplier/Symbol | O24: Chance | P24: EV
A25: Chance: | B25: =B16/B17 * 4 -> 0.78947368 | C25: =C16/C17 * 4 -> 0.81081081 | D25: =D16/D17 * 4 -> 0.81081081 | E25: =E16/E17 * 4 -> 0.81081081 | F25: =F16/F17 * 4 -> 0.78947368 | H25: =A4 -> H1 | I25: =I4 * N4 -> 0.0012449255 | J25: =J4 * O4 -> 0.00020210429 | K25: =K4 * P4 -> 4.1528278e-05 | L25: =SUM(I25:K25) -> 0.001488558 | N25: 0.5 | O25: =1-SUM(O26:O45) -> 0.2781 | P25: =N25 * O25 -> 0.13905 | R25: =SUM(O$25:O25) * 10000 -> 2781
A26: Ave Win: | B26: =$P46 -> 2.03005 | C26: =$P46 -> 2.03005 | D26: =$P46 -> 2.03005 | E26: =$P46 -> 2.03005 | F26: =$P46 -> 2.03005 | H26: =A5 -> H2 | I26: =I5 * N5 -> 0.0023274976 | J26: =J5 * O5 -> 0.00047249952 | K26: =K5 * P5 -> 8.749991e-05 | L26: =SUM(I26:K26) -> 0.002887497 | N26: 1 | O26: 0.27 | P26: =N26 * O26 -> 0.27 | R26: =SUM(O$25:O26) * 10000 -> 5481
A27: EV | B27: =B25 * B26 -> 1.6026711 | C27: =C25 * C26 -> 1.6459865 | D27: =D25 * D26 -> 1.6459865 | E27: =E25 * E26 -> 1.6459865 | F27: =F25 * F26 -> 1.6026711 | H27: =A6 -> H3 | I27: =I6 * N6 -> 0.0033607143 | J27: =J6 * O6 -> 0.00075836104 | K27: =K6 * P6 -> 0.00016021712 | L27: =SUM(I27:K27) -> 0.0042792925 | N27: 1.5 | O27: 0.12 | P27: =N27 * O27 -> 0.18 | R27: =SUM(O$25:O27) * 10000 -> 6681
H28: =A7 -> H4 | I28: =I7 * N7 -> 0.0038154336 | J28: =J7 * O7 -> 0.0010852723 | K28: =K7 * P7 -> 0.00026578098 | L28: =SUM(I28:K28) -> 0.0051664869 | N28: 2 | O28: 0.09 | P28: =N28 * O28 -> 0.18 | R28: =SUM(O$25:O28) * 10000 -> 7581
H29: =A8 -> H5 | I29: =I8 * N8 -> 0.0059696677 | J29: =J8 * O8 -> 0.0019818781 | K29: =K8 * P8 -> 0.00057445742 | L29: =SUM(I29:K29) -> 0.0085260032 | N29: 2.5 | O29: 0.06 | P29: =N29 * O29 -> 0.15 | R29: =SUM(O$25:O29) * 10000 -> 8181
H30: =A9 -> L1 | I30: =I9 * N9 -> 0.008777991 | J30: =J9 * O9 -> 0.0019039981 | K30: =K9 * P9 -> 0.00083999914 | L30: =SUM(I30:K30) -> 0.011521988 | N30: 3 | O30: 0.04 | P30: =N30 * O30 -> 0.12 | R30: =SUM(O$25:O30) * 10000 -> 8581
A31: QH Chance | B31: =B3 -> Reel1 | C31: =C3 -> Reel2 | D31: =D3 -> Reel3 | E31: =E3 -> Reel4 | F31: =F3 -> Reel5 | H31: =A10 -> L2 | I31: =I10 * N10 -> 0.008777991 | J31: =J10 * O10 -> 0.0019039981 | K31: =K10 * P10 -> 0.00083999914 | L31: =SUM(I31:K31) -> 0.011521988 | N31: 3.5 | O31: 0.03 | P31: =N31 * O31 -> 0.105 | R31: =SUM(O$25:O31) * 10000 -> 8881
A32: Hit: | B32: =SUM(B62:B64) -> 0.51315789 | C32: =SUM(C62:C64) -> 0.52702703 | D32: =SUM(D62:D64) -> 0.52702703 | E32: =SUM(E62:E64) -> 0.52702703 | F32: =SUM(F62:F64) -> 0.51315789 | H32: =A11 -> L3 | I32: =I11 * N11 -> 0.0061544908 | J32: =J11 * O11 -> 0.0022537396 | K32: =K11 * P11 -> 0.0010091372 | L32: =SUM(I32:K32) -> 0.0094173676 | N32: 4 | O32: 0.025 | P32: =N32 * O32 -> 0.1 | R32: =SUM(O$25:O32) * 10000 -> 9131
A33: No Hit: | B33: =B65 -> 0.48684211 | C33: =C65 -> 0.47297297 | D33: =D65 -> 0.47297297 | E33: =E65 -> 0.47297297 | F33: =F65 -> 0.48684211 | H33: =A12 -> L4 | I33: =I12 * N12 -> 0.0061544908 | J33: =J12 * O12 -> 0.0022537396 | K33: =K12 * P12 -> 0.0010091372 | L33: =SUM(I33:K33) -> 0.0094173676 | N33: 5 | O33: 0.02 | P33: =N33 * O33 -> 0.1 | R33: =SUM(O$25:O33) * 10000 -> 9331
H34: =A13 -> W | I34: =I13 * N13 -> 0 | J34: =J13 * O13 -> 0 | K34: =K13 * P13 -> 0 | L34: =SUM(I34:K34) -> 0 | N34: 6 | O34: 0.015 | P34: =N34 * O34 -> 0.09 | R34: =SUM(O$25:O34) * 10000 -> 9481
A35: QH on Reel1 to 4 | D35: QH on Reel2 to 5 | N35: 7 | O35: 0.012 | P35: =N35 * O35 -> 0.084 | R35: =SUM(O$25:O35) * 10000 -> 9601
A36: Chance of no QH: | B36: =B33 * C33 * D33 * E33 -> 0.051510659 | D36: Chance of no QH: | E36: =C33 * D33 * E33 * F33 -> 0.051510659 | N36: 8 | O36: 0.01 | P36: =N36 * O36 -> 0.08 | R36: =SUM(O$25:O36) * 10000 -> 9701
A37: Chance of QH: | B37: =1-B36 -> 0.94848934 | D37: Chance of QH: | E37: =1-E36 -> 0.94848934 | N37: 9 | O37: 0.008 | P37: =N37 * O37 -> 0.072 | R37: =SUM(O$25:O37) * 10000 -> 9781
A38: Chance of Collect: | B38: =B21 -> 0.10526316 | D38: Chance of Collect: | E38: =B20 -> 0.10526316 | N38: 10 | O38: 0.006 | P38: =N38 * O38 -> 0.06 | R38: =SUM(O$25:O38) * 10000 -> 9841
I39: =SUM(I25:I38) -> 0.046583202 | J39: =SUM(J25:J38) -> 0.012815591 | K39: =SUM(K25:K38) -> 0.0048277563 | L39: =SUM(L25:L38) -> 0.064226549 | N39: 12 | O39: 0.005 | P39: =N39 * O39 -> 0.06 | R39: =SUM(O$25:O39) * 10000 -> 9891
A40: Chance of a Win: | B40: =B37 * B38 -> 0.099840983 | D40: Chance of a Win: | E40: =E37 * E38 -> 0.099840983 | N40: 15 | O40: 0.004 | P40: =N40 * O40 -> 0.06 | R40: =SUM(O$25:O40) * 10000 -> 9931
N41: 20 | O41: 0.003 | P41: =N41 * O41 -> 0.06 | R41: =SUM(O$25:O41) * 10000 -> 9961
N42: 25 | O42: 0.002 | P42: =N42 * O42 -> 0.05 | R42: =SUM(O$25:O42) * 10000 -> 9981
N43: 30 | O43: 0.001 | P43: =N43 * O43 -> 0.03 | R43: =SUM(O$25:O43) * 10000 -> 9991
N44: 40 | O44: 0.0005 | P44: =N44 * O44 -> 0.02 | R44: =SUM(O$25:O44) * 10000 -> 9996
...

Sheet BaseB_Structure
A1: "L3", | B1: "L2", | C1: "H5", | D1: "H5", | E1: "L1",
A2: "L2", | B2: "L3", | C2: "L4", | D2: "H3", | E2: "L4",
A3: "L2", | B3: "H4", | C3: "L1", | D3: "H1", | E3: "L4",
A4: "QH", | B4: "QH", | C4: "QH", | D4: "QH", | E4: "QH",
A5: "QH", | B5: "QH", | C5: "QH", | D5: "QH", | E5: "QH",
A6: "QH", | B6: "QH", | C6: "QH", | D6: "QH", | E6: "QH",
A7: "L4", | B7: "L1", | C7: "L2", | D7: "L4", | E7: "L3",
A8: "H4", | B8: "H5", | C8: "L4", | D8: "H2", | E8: "L2", | G8: "QH",
A9: "H5", | B9: "H3", | C9: "H3", | D9: "H4", | E9: "H5", | G9: "C",
A10: "L4", | B10: "H5", | C10: "L3", | D10: "L2", | E10: "L1",
A11: "C", | B11: "L4", | C11: "H5", | D11: "L3", | E11: "C",
A12: "L2", | B12: "H4", | C12: "L4", | D12: "H4", | E12: "H1",
A13: "H4", | B13: "L4", | C13: "L2", | D13: "H5", | E13: "H4",
A14: "H4", | B14: "L4", | C14: "H4", | D14: "L1", | E14: "H4",
A15: "L1", | B15: "H2", | C15: "H4", | D15: "L4", | E15: "H5",
A16: "QH", | B16: "QH", | C16: "QH", | D16: "QH", | E16: "QH",
A17: "L1", | B17: "H5", | C17: "L2", | D17: "L4", | E17: "L2",
A18: "H3", | B18: "L1", | C18: "H3", | D18: "L4", | E18: "H3",
A19: "L3", | B19: "L4", | C19: "L4", | D19: "H5", | E19: "H5",
A20: "H4", | B20: "H1", | C20: "L1", | D20: "L1", | E20: "L1",
A21: "H2", | B21: "H2", | C21: "L4", | D21: "L3", | E21: "L3",
... A74: "H3", | B74: "L1", | C74: "H2", | D74: "H3", | E74: "L3",
A75: "L3", | E75: "H3",
A76: "H2", | E76: "L1",

Sheet Structure
A1: "H1", | B1: 32 | C1: 32 | D1: 32 | E1: 32 | F1: =E1 * 1.5 -> 48
A2: "H2", | B2: 48 | C2: 48 | D2: 48 | E2: 48 | F2: =E2 * 1.5 -> 72
A3: "H3", | B3: 64 | C3: 64 | D3: 64 | E3: 64 | F3: =E3 * 1.5 -> 96
A4: "H4", | B4: 80 | C4: 80 | D4: 80 | E4: 80 | F4: =E4 * 1.5 -> 120
A5: "H5", | B5: 96 | C5: 96 | D5: 96 | E5: 96 | F5: =E5 * 1.5 -> 144
A6: "L1", | B6: 112 | C6: 112 | D6: 112 | E6: 112 | F6: =E6 * 1.5 -> 168
A7: "L2", | B7: 112 | C7: 112 | D7: 112 | E7: 112 | F7: =E7 * 1.5 -> 168
A8: "L3", | B8: 128 | C8: 128 | D8: 128 | E8: 128 | F8: =E8 * 1.5 -> 192
A9: "L4", | B9: 128 | C9: 128 | D9: 128 | E9: 128 | F9: =E9 * 1.5 -> 192
A10: "W", | B10: 0 | C10: 0 | D10: 0 | E10: 0 | F10: =E10 * 1.5 -> 0
A11: rn1, | B11: 0 | C11: 0 | D11: 0 | E11: 0 | F11: =E11 * 1.5 -> 0
A12: "C",
A16: Total | B16: =SUM(B1:B15) -> 800 | C16: =SUM(C1:C15) -> 800 | D16: =SUM(D1:D15) -> 800 | E16: =SUM(E1:E15) -> 800 | F16: =SUM(F1:F15) -> 1200

Sheet BaseC
A1: BaseC | D1: RTP: | E1: =L39 -> 0.059062853 | G1: Final RTP: | H1: =E1 + K1 + N1 -> 0.98421665 | J1: QH RTP: | K1: =B21 * F21 -> 0.13827438 | M1: =BaseB!M1 -> Bonus RTP: | N1: =I15 * N15 + J15 * O15 + K15 * P15 + L15 * Q15 -> 0.78687942
A2: Number of Symbol | H2: Chances | M2: Math Payout
A3: Pattern | B3: Reel1 | C3: Reel2 | D3: Reel3 | E3: Reel4 | F3: Reel5 | H3: Pattern | I3: 3Hit | J3: 4Hit | K3: 5Hit | M3: Pattern | N3: =I3 -> 3Hit | O3: =J3 -> 4Hit | P3: =K3 -> 5Hit
A4: H1 | B4: 3 | C4: 3 | D4: 3 | E4: 3 | F4: 48 | H4: =A4 -> H1 | I4: =(B4+B$13)/B$17 * (C4+C$13)/C$17 * (D4+D$13)/D$17 * (E$17-E4-E$13)/E$17 - (B$13)/B$17 * (C$13)/C$17 * (D$13)/D$17 * (E$17-E4-E$13)/E$17 -> 5.6837188e-05 | J4: =(B4+B$13)/B$17 * (C4+C$13)/C$17 * (D4+D$13)/D$17 * (E4+E$13)/E$17 * (F$17 - F4-F$13)/F$17 - (B$13)/B$17 * (C$13)/C$17 * (D$13)/D$17 * (E$13)/E$17 * (F$17 - F4-F$13)/F$17 -> 2.2121187e-06 | K4: =(B4+B$13)/B$17 * (C4+C$13)/C$17 * (D4+D$13)/D$17 * (E4+E$13)/E$17 * (F4+F$13)/F$17 - (B$13)/B$17 * (C$13)/C$17 * (D$13)/D$17 * (E$13)/E$17 * (F$13)/F$17 -> 9.209167e-08 | M4: =H4 -> H1 | N4: =BaseA!N4 -> 20 | O4: =BaseA!O4 -> 80 | P4: =BaseA!P4 -> 400
A5: H2 | B5: 4 | C5: 4 | D5: 4 | E5: 4 | F5: 72 | H5: =A5 -> H2 | I5: =(B5+B$13)/B$17 * (C5+C$13)/C$17 * (D5+D$13)/D$17 * (E$17-E5-E$13)/E$17 - (B$13)/B$17 * (C$13)/C$17 * (D$13)/D$17 * (E$17-E5-E$13)/E$17 -> 0.00013290458 | J5: =(B5+B$13)/B$17 * (C5+C$13)/C$17 * (D5+D$13)/D$17 * (E5+E$13)/E$17 * (F$17 - F5-F$13)/F$17 - (B$13)/B$17 * (C$13)/C$17 * (D$13)/D$17 * (E$13)/E$17 * (F$17 - F5-F$13)/F$17 -> 6.8458598e-06 | K5: =(B5+B$13)/B$17 * (C5+C$13)/C$17 * (D5+D$13)/D$17 * (E5+E$13)/E$17 * (F5+F$13)/F$17 - (B$13)/B$17 * (C$13)/C$17 * (D$13)/D$17 * (E$13)/E$17 * (F5 + F$13)/F$17 -> 4.3658273e-07 | M5: =H5 -> H2 | N5: =BaseA!N5 -> 16 | O5: =BaseA!O5 -> 60 | P5: =BaseA!P5 -> 200
A6: H3 | B6: 5 | C6: 5 | D6: 5 | E6: 5 | F6: 96 | H6: =A6 -> H3 | I6: =(B6+B$13)/B$17 * (C6+C$13)/C$17 * (D6+D$13)/D$17 * (E$17-E6-E$13)/E$17 - (B$13)/B$17 * (C$13)/C$17 * (D$13)/D$17 * (E$17-E6-E$13)/E$17 -> 0.00025602337 | J6: =(B6+B$13)/B$17 * (C6+C$13)/C$17 * (D6+D$13)/D$17 * (E6+E$13)/E$17 * (F$17 - F6-F$13)/F$17 - (B$13)/B$17 * (C$13)/C$17 * (D$13)/D$17 * (E6 + E$13)/E$17 * (F$17 - F6-F$13)/F$17 -> 1.6358233e-05 | K6: =(B6+B$13)/B$17 * (C6+C$13)/C$17 * (D6+D$13)/D$17 * (E6+E$13)/E$17 * (F6+F$13)/F$17 - (B$13)/B$17 * (C$13)/C$17 * (D$13)/D$17 * (E$13)/E$17 * (F6 + F$13)/F$17 -> 1.4211677e-06 | M6: =H6 -> H3 | N6: =BaseA!N6 -> 12 | O6: =BaseA!O6 -> 40 | P6: =BaseA!P6 -> 120
A7: H4 | B7: 6 | C7: 6 | D7: 6 | E7: 6 | F7: 120 | H7: =A7 -> H4 | I7: =(B7+B$13)/B$17 * (C7+C$13)/C$17 * (D7+D$13)/D$17 * (E$17-E7-E$13)/E$17 - (B$13)/B$17 * (C$13)/C$17 * (D$13)/D$17 * (E$17-E7-E$13)/E$17 -> 0.00043626382 | J7: =(B7+B$13)/B$17 * (C7+C$13)/C$17 * (D7+D$13)/D$17 * (E7+E$13)/E$17 * (F$17 - F7-F$13)/F$17 - (B$13)/B$17 * (C$13)/C$17 * (D$13)/D$17 * (E7 + E$13)/E$17 * (F$17 - F7-F$13)/F$17 -> 3.3183698e-05 | K7: =(B7+B$13)/B$17 * (C7+C$13)/C$17 * (D7+D$13)/D$17 * (E7+E$13)/E$17 * (F7+F$13)/F$17 - (B$13)/B$17 * (C$13)/C$17 * (D$13)/D$17 * (E$13)/E$17 * (F7 + F$13)/F$17 -> 3.6836668e-06 | M7: =H7 -> H4 | N7: =BaseA!N7 -> 8 | O7: =BaseA!O7 -> 28 | P7: =BaseA!P7 -> 80
A8: H5 | B8: 7 | C8: 7 | D8: 7 | E8: 7 | F8: 144 | H8: =A8 -> H5 | I8: =(B8+B$13)/B$17 * (C8+C$13)/C$17 * (D8+D$13)/D$17 * (E$17-E8-E$13)/E$17 - (B$13)/B$17 * (C$13)/C$17 * (D$13)/D$17 * (E$17-E8-E$13)/E$17 -> 0.00068301346 | J8: =(B8+B$13)/B$17 * (C8+C$13)/C$17 * (D8+D$13)/D$17 * (E8+E$13)/E$17 * (F$17 - F8-F$13)/F$17 - (B$13)/B$17 * (C$13)/C$17 * (D$13)/D$17 * (E8 + E$13)/E$17 * (F$17 - F8-F$13)/F$17 -> 6.0112009e-05 | K8: =(B8+B$13)/B$17 * (C8+C$13)/C$17 * (D8+D$13)/D$17 * (E8+E$13)/E$17 * (F8+F$13)/F$17 - (B$13)/B$17 * (C$13)/C$17 * (D$13)/D$17 * (E$13)/E$17 * (F8 + F$13)/F$17 -> 8.189337e-06 | M8: =H8 -> H5 | N8: =BaseA!N8 -> 8 | O8: =BaseA!O8 -> 28 | P8: =BaseA!P8 -> 80
A9: L1 | B9: 8 | C9: 8 | D9: 8 | E9: 8 | F9: 168 | H9: =A9 -> L1 | I9: =(B9+B$13)/B$17 * (C9+C$13)/C$17 * (D9+D$13)/D$17 * (E$17-E9-E$13)/E$17 - (B$13)/B$17 * (C$13)/C$17 * (D$13)/D$17 * (E$17-E9-E$13)/E$17 -> 0.0010049771 | J9: =(B9+B$13)/B$17 * (C9+C$13)/C$17 * (D9+D$13)/D$17 * (E9+E$13)/E$17 * (F$17 - F9-F$13)/F$17 - (B$13)/B$17 * (C$13)/C$17 * (D$13)/D$17 * (E9 + E$13)/E$17 * (F$17 - F9-F$13)/F$17 -> 0.00010021999 | K9: =(B9+B$13)/B$17 * (C9+C$13)/C$17 * (D9+D$13)/D$17 * (E9+E$13)/E$17 * (F9+F$13)/F$17 - (B$13)/B$17 * (C$13)/C$17 * (D$13)/D$17 * (E$13)/E$17 * (F9 + F$13)/F$17 -> 1.6299089e-05 | M9: =H9 -> L1 | N9: =BaseA!N9 -> 8 | O9: =BaseA!O9 -> 16 | P9: =BaseA!P9 -> 60
A10: L2 | B10: 8 | C10: 8 | D10: 8 | E10: 8 | F10: 168 | H10: =A10 -> L2 | I10: =(B10+B$13)/B$17 * (C10+C$13)/C$17 * (D10+D$13)/D$17 * (E$17-E10-E$13)/E$17 - (B$13)/B$17 * (C$13)/C$17 * (D$13)/D$17 * (E$17-E10-E$13)/E$17 -> 0.0010049771 | J10: =(B10+B$13)/B$17 * (C10+C$13)/C$17 * (D10+D$13)/D$17 * (E10+E$13)/E$17 * (F$17 - F10-F$13)/F$17 - (B$13)/B$17 * (C$13)/C$17 * (D$13)/D$17 * (E10 + E$13)/E$17 * (F$17 - F10-F$13)/F$17 -> 0.00010021999 | K10: =(B10+B$13)/B$17 * (C10+C$13)/C$17 * (D10+D$13)/D$17 * (E10+E$13)/E$17 * (F10+F$13)/F$17 - (B$13)/B$17 * (C$13)/C$17 * (D$13)/D$17 * (E$13)/E$17 * (F10 + F$13)/F$17 -> 1.6299089e-05 | M10: =H10 -> L2 | N10: =BaseA!N10 -> 8 | O10: =BaseA!O10 -> 16 | P10: =BaseA!P10 -> 60
A11: L3 | B11: 9 | C11: 9 | D11: 9 | E11: 9 | F11: 192 | H11: =A11 -> L3 | I11: =(B11+B$13)/B$17 * (C11+C$13)/C$17 * (D11+D$13)/D$17 * (E$17-E11-E$13)/E$17 - (B$13)/B$17 * (C$13)/C$17 * (D$13)/D$17 * (E$17-E11-E$13)/E$17 -> 0.0014101767 | J11: =(B11+B$13)/B$17 * (C11+C$13)/C$17 * (D11+D$13)/D$17 * (E11+E$13)/E$17 * (F$17 - F11-F$13)/F$17 - (B$13)/B$17 * (C$13)/C$17 * (D$13)/D$17 * (E11 + E$13)/E$17 * (F$17 - F11-F$13)/F$17 -> 0.00015680334 | K11: =(B11+B$13)/B$17 * (C11+C$13)/C$17 * (D11+D$13)/D$17 * (E11+E$13)/E$17 * (F11+F$13)/F$17 - (B$13)/B$17 * (C$13)/C$17 * (D$13)/D$17 * (E11+E$13)/E$17 * (F11 + F$13)/F$17 -> 2.9837701e-05 | M11: =H11 -> L3 | N11: =BaseA!N11 -> 4 | O11: =BaseA!O11 -> 12 | P11: =BaseA!P11 -> 40
